Workbook
Name Slicer_Account_Type: #N/A
Name Slicer_Payment_Method: #N/A
Name Slicer_State: #N/A

Sheet Raw_Data
A1: Transaction_ID | B1: Customer_ID | C1: Transaction_Date | D1: Transaction_Type | E1: Amount | F1: Transaction_Status | G1: Customer_Age | H1: Gender | I1: State | J1: Account_Type | K1: Payment_Method
A2: TXN-20250001 | B2: CUST-0043 | C2: 45672.164 | D2: Airtime/Data | E2: 1638.03 | F2: Successful | G2: 47 | H2: Male | I2: Ogun | J2: Savings | K2: Bank Transfer
A3: TXN-20250002 | B3: CUST-0277 | C3: 45791.234 | D3: Airtime/Data | E3: 994.07 | F3: Successful | G3: 43 | H3: Male | I3: Kano | J3: Savings | K3: Wallet Balance
A4: TXN-20250003 | B4: CUST-0265 | C4: 45793.046 | D4: Airtime/Data | E4: 2862.66 | F4: Successful | G4: 35 | H4: Male | I4: Oyo | J4: Savings | K4: Bank Transfer
A5: TXN-20250004 | B5: CUST-0052 | C5: 45963.557 | D5: Transfer | E5: 39577 | F5: Successful | G5: 35 | H5: Female | I5: Edo | J5: Savings | K5: Bank Transfer
A6: TXN-20250005 | B6: CUST-0276 | C6: 45818.568 | D6: Bill Payment | E6: 21734.4 | F6: Successful | G6: 53 | H6: Male | I6: Lagos | J6: Savings | K6: USSD
A7: TXN-20250006 | B7: CUST-0233 | C7: 45919.142 | D7: POS Payment | E7: 14388.09 | F7: Successful | G7: 29 | H7: Male | I7: Oyo | J7: Savings | K7: Bank Transfer
A8: TXN-20250007 | B8: CUST-0312 | C8: 45953.261 | D8: Airtime/Data | E8: 1290.67 | F8: Successful | G8: 36 | H8: Female | I8: Lagos | J8: Savings | K8: Bank Transfer
A9: TXN-20250008 | B9: CUST-0308 | C9: 45680.935 | D9: Transfer | E9: 2614.16 | F9: Successful | G9: 35 | H9: Male | I9: Enugu | J9: Tier 1 Wallet | K9: Debit Card
A10: TXN-20250009 | B10: CUST-0229 | C10: 45658.708 | D10: Transfer | E10: 1856.41 | F10: Successful | G10: 53 | H10: Male | I10: Rivers | J10: Current | K10: Bank Transfer
A11: TXN-20250010 | B11: CUST-0035 | C11: 45933.907 | D11: POS Payment | E11: 827.07 | F11: Successful | G11: 30 | H11: Female | I11: Rivers | J11: Tier 3 Verified | K11: Bank Transfer
A12: TXN-20250011 | B12: CUST-0088 | C12: 46001.266 | D12: Transfer | E12: 45733.52 | F12: Successful | G12: 60 | H12: Female | I12: Lagos | J12: Current | K12: USSD
A13: TXN-20250012 | B13: CUST-0178 | C13: 45878.113 | D13: Airtime/Data | E13: 774.66 | F13: Failed | G13: 64 | H13: Female | I13: Edo | J13: Current | K13: Debit Card
... A2501: TXN-20252500 | B2501: CUST-0248 | C2501: 45926.383 | D2501: Airtime/Data | E2501: 1858.4 | F2501: Successful | G2501: 30 | H2501: Male | I2501: FCT Abuja | J2501: Current | K2501: Bank Transfer

Sheet Obj1_Volume_and_Value
B2: OBJECTIVE 1 · TRANSACTION VOLUME & VALUE
B3: Core questions: How much total money is being transacted? What are the key aggregate platform metrics?
B5: KPI SUMMARY
B6: Metric | C6: Value | D6: Live Excel Formula
B7: Total Transaction Value (₦) | C7: =SUM(TransactionTable[Amount]) -> 36963243 | D7: =_xlfn.FORMULATEXT(C7) -> =SUM(TransactionTable[Amount])
B8: Total Volume (Transactions) | C8: =COUNTA(TransactionTable[Transaction_ID]) -> 2500 | D8: =_xlfn.FORMULATEXT(C8) -> =COUNTA(TransactionTable[Transaction_ID])
B9: Average Transaction Value (₦) | C9: =AVERAGE(TransactionTable[Amount]) -> 14785.297 | D9: =_xlfn.FORMULATEXT(C9) -> =AVERAGE(TransactionTable[Amount])
B10: Successful Rate (%) | C10: =COUNTIF(TransactionTable[Transaction_Status],"Successful")/C8 -> 0.8832 | D10: =_xlfn.FORMULATEXT(C10) -> =COUNTIF(TransactionTable[Transaction_Status],"Successful")/C8
B11: Failed Rate (%) | C11: =COUNTIF(TransactionTable[Transaction_Status],"Failed")/C8 -> 0.0956 | D11: =_xlfn.FORMULATEXT(C11) -> =COUNTIF(TransactionTable[Transaction_Status],"Failed")/C8
B14: OPERATIONAL HEALTH · TRANSACTION STATUS BREAKDOWN
B15: Transaction Status | C15: Transaction Count | D15: % of Volume | E15: Transaction Value (₦) | F15: % of Value | G15: Avg Value (₦)
B16: Successful | C16: =COUNTIF(TransactionTable[Transaction_Status],B16) -> 2208 | D16: =C16/$C$19 -> 0.8832 | E16: =SUMIF(TransactionTable[Transaction_Status],B16,TransactionTable[Amount]) -> 32313273 | F16: =E16/$E$19 -> 0.87420016 | G16: =IFERROR(E16/C16,0) -> 14634.634
B17: Failed | C17: =COUNTIF(TransactionTable[Transaction_Status],B17) -> 239 | D17: =C17/$C$19 -> 0.0956 | E17: =SUMIF(TransactionTable[Transaction_Status],B17,TransactionTable[Amount]) -> 3743318.1 | F17: =E17/$E$19 -> 0.10127137 | G17: =IFERROR(E17/C17,0) -> 15662.419
B18: Pending | C18: =COUNTIF(TransactionTable[Transaction_Status],B18) -> 53 | D18: =C18/$C$19 -> 0.0212 | E18: =SUMIF(TransactionTable[Transaction_Status],B18,TransactionTable[Amount]) -> 906651.76 | F18: =E18/$E$19 -> 0.024528469 | G18: =IFERROR(E18/C18,0) -> 17106.637
B19: Total | C19: =SUM(C16:C18) -> 2500 | D19: =SUM(D16:D18) -> 1 | E19: =SUM(E16:E18) -> 36963243 | F19: =SUM(F16:F18) -> 1 | G19: =IFERROR(E19/C19,0) -> 14785.297
B20: Reconciliation check | C20: =IF(AND(C19=C8,ROUND(E19-C7,2)=0),"✔ Reconciles to KPI totals","✖ Check source data") -> ✔ Reconciles to KPI totals
B22: KEY TAKEAWAYS
B23: ="• ₦"&TEXT(C7,"#,##0.00")&" transacted across "&TEXT(C8,"#,##0")&" transactions, averaging ₦"&TEXT(C9,"#,##0.00")&" per transaction." -> • ₦36,963,242.61 transacted across 2,500 transactions, averaging ₦14,785.30 per transaction.
B24: ="• Realised (successful) value is ₦"&TEXT(E16,"#,##0.00")&" — "&TEXT(F16,"0.0%")&" of attempted value." -> • Realised (successful) value is ₦32,313,272.70 — 87.4% of attempted value.
B25: ="• Failed transactions put ₦"&TEXT(E17,"#,##0.00")&" ("&TEXT(F17,"0.0%")&" of value) at risk; a further ₦"&TEXT(E18,"#,##0.00")&" is pending." -> • Failed transactions put ₦3,743,318.15 (10.1% of value) at risk; a further ₦906,651.76 is pending.

Sheet Obj2_High_Value_Customers
B2: OBJECTIVE 2 · HIGH-VALUE CUSTOMERS & SEGMENTS
B3: Core questions: Which customer segments and top individuals generate the most transaction value?
B5: TOP 10 CUSTOMERS BY CUMULATIVE TRANSACTION VALUE | R5: CUSTOMER LEDGER (supporting calculation for ranking)
B6: Rank | C6: Customer_ID | D6: State | E6: Account_Type | F6: Total Spent (₦) | G6: Transaction Count | H6: % of Platform Value | R6: Customer_ID | S6: State | T6: Account_Type | U6: Total Spent (₦) | V6: Txn Count | W6: Rank Key (tie-break)
B7: 1 | C7: =INDEX($R$7:$R$356,MATCH(LARGE($W$7:$W$356,B7),$W$7:$W$356,0)) -> CUST-0179 | D7: =INDEX($S$7:$S$356,MATCH(LARGE($W$7:$W$356,B7),$W$7:$W$356,0)) -> Delta | E7: =INDEX($T$7:$T$356,MATCH(LARGE($W$7:$W$356,B7),$W$7:$W$356,0)) -> Tier 1 Wallet | F7: =INDEX($U$7:$U$356,MATCH(LARGE($W$7:$W$356,B7),$W$7:$W$356,0)) -> 374370.26 | G7: =INDEX($V$7:$V$356,MATCH(LARGE($W$7:$W$356,B7),$W$7:$W$356,0)) -> 8 | H7: =F7/SUM(TransactionTable[Amount]) -> 0.010128177 | R7: CUST-0001 | S7: =INDEX(TransactionTable[State],MATCH(R7,TransactionTable[Customer_ID],0)) -> Delta | T7: =INDEX(TransactionTable[Account_Type],MATCH(R7,TransactionTable[Customer_ID],0)) -> Tier 1 Wallet | U7: =SUMIFS(TransactionTable[Amount],TransactionTable[Customer_ID],R7) -> 28698.58 | V7: =COUNTIF(TransactionTable[Customer_ID],R7) -> 6 | W7: =U7+ROW()/10^7 -> 28698.58
B8: 2 | C8: =INDEX($R$7:$R$356,MATCH(LARGE($W$7:$W$356,B8),$W$7:$W$356,0)) -> CUST-0034 | D8: =INDEX($S$7:$S$356,MATCH(LARGE($W$7:$W$356,B8),$W$7:$W$356,0)) -> Lagos | E8: =INDEX($T$7:$T$356,MATCH(LARGE($W$7:$W$356,B8),$W$7:$W$356,0)) -> Current | F8: =INDEX($U$7:$U$356,MATCH(LARGE($W$7:$W$356,B8),$W$7:$W$356,0)) -> 349166.65 | G8: =INDEX($V$7:$V$356,MATCH(LARGE($W$7:$W$356,B8),$W$7:$W$356,0)) -> 10 | H8: =F8/SUM(TransactionTable[Amount]) -> 0.0094463209 | R8: CUST-0002 | S8: =INDEX(TransactionTable[State],MATCH(R8,TransactionTable[Customer_ID],0)) -> Lagos | T8: =INDEX(TransactionTable[Account_Type],MATCH(R8,TransactionTable[Customer_ID],0)) -> Savings | U8: =SUMIFS(TransactionTable[Amount],TransactionTable[Customer_ID],R8) -> 69191.52 | V8: =COUNTIF(TransactionTable[Customer_ID],R8) -> 5 | W8: =U8+ROW()/10^7 -> 69191.52
B9: 3 | C9: =INDEX($R$7:$R$356,MATCH(LARGE($W$7:$W$356,B9),$W$7:$W$356,0)) -> CUST-0329 | D9: =INDEX($S$7:$S$356,MATCH(LARGE($W$7:$W$356,B9),$W$7:$W$356,0)) -> Rivers | E9: =INDEX($T$7:$T$356,MATCH(LARGE($W$7:$W$356,B9),$W$7:$W$356,0)) -> Current | F9: =INDEX($U$7:$U$356,MATCH(LARGE($W$7:$W$356,B9),$W$7:$W$356,0)) -> 325244.08 | G9: =INDEX($V$7:$V$356,MATCH(LARGE($W$7:$W$356,B9),$W$7:$W$356,0)) -> 8 | H9: =F9/SUM(TransactionTable[Amount]) -> 0.008799122 | R9: CUST-0003 | S9: =INDEX(TransactionTable[State],MATCH(R9,TransactionTable[Customer_ID],0)) -> Ogun | T9: =INDEX(TransactionTable[Account_Type],MATCH(R9,TransactionTable[Customer_ID],0)) -> Current | U9: =SUMIFS(TransactionTable[Amount],TransactionTable[Customer_ID],R9) -> 112426.03 | V9: =COUNTIF(TransactionTable[Customer_ID],R9) -> 7 | W9: =U9+ROW()/10^7 -> 112426.03
B10: 4 | C10: =INDEX($R$7:$R$356,MATCH(LARGE($W$7:$W$356,B10),$W$7:$W$356,0)) -> CUST-0164 | D10: =INDEX($S$7:$S$356,MATCH(LARGE($W$7:$W$356,B10),$W$7:$W$356,0)) -> Kano | E10: =INDEX($T$7:$T$356,MATCH(LARGE($W$7:$W$356,B10),$W$7:$W$356,0)) -> Current | F10: =INDEX($U$7:$U$356,MATCH(LARGE($W$7:$W$356,B10),$W$7:$W$356,0)) -> 273501.11 | G10: =INDEX($V$7:$V$356,MATCH(LARGE($W$7:$W$356,B10),$W$7:$W$356,0)) -> 10 | H10: =F10/SUM(TransactionTable[Amount]) -> 0.0073992726 | R10: CUST-0004 | S10: =INDEX(TransactionTable[State],MATCH(R10,TransactionTable[Customer_ID],0)) -> Lagos | T10: =INDEX(TransactionTable[Account_Type],MATCH(R10,TransactionTable[Customer_ID],0)) -> Tier 3 Verified | U10: =SUMIFS(TransactionTable[Amount],TransactionTable[Customer_ID],R10) -> 175479.31 | V10: =COUNTIF(TransactionTable[Customer_ID],R10) -> 6 | W10: =U10+ROW()/10^7 -> 175479.31
B11: 5 | C11: =INDEX($R$7:$R$356,MATCH(LARGE($W$7:$W$356,B11),$W$7:$W$356,0)) -> CUST-0251 | D11: =INDEX($S$7:$S$356,MATCH(LARGE($W$7:$W$356,B11),$W$7:$W$356,0)) -> Delta | E11: =INDEX($T$7:$T$356,MATCH(LARGE($W$7:$W$356,B11),$W$7:$W$356,0)) -> Current | F11: =INDEX($U$7:$U$356,MATCH(LARGE($W$7:$W$356,B11),$W$7:$W$356,0)) -> 269972.16 | G11: =INDEX($V$7:$V$356,MATCH(LARGE($W$7:$W$356,B11),$W$7:$W$356,0)) -> 11 | H11: =F11/SUM(TransactionTable[Amount]) -> 0.0073038008 | R11: CUST-0005 | S11: =INDEX(TransactionTable[State],MATCH(R11,TransactionTable[Customer_ID],0)) -> Lagos | T11: =INDEX(TransactionTable[Account_Type],MATCH(R11,TransactionTable[Customer_ID],0)) -> Savings | U11: =SUMIFS(TransactionTable[Amount],TransactionTable[Customer_ID],R11) -> 106835.97 | V11: =COUNTIF(TransactionTable[Customer_ID],R11) -> 7 | W11: =U11+ROW()/10^7 -> 106835.97
B12: 6 | C12: =INDEX($R$7:$R$356,MATCH(LARGE($W$7:$W$356,B12),$W$7:$W$356,0)) -> CUST-0116 | D12: =INDEX($S$7:$S$356,MATCH(LARGE($W$7:$W$356,B12),$W$7:$W$356,0)) -> Oyo | E12: =INDEX($T$7:$T$356,MATCH(LARGE($W$7:$W$356,B12),$W$7:$W$356,0)) -> Savings | F12: =INDEX($U$7:$U$356,MATCH(LARGE($W$7:$W$356,B12),$W$7:$W$356,0)) -> 263967.93 | G12: =INDEX($V$7:$V$356,MATCH(LARGE($W$7:$W$356,B12),$W$7:$W$356,0)) -> 7 | H12: =F12/SUM(TransactionTable[Amount]) -> 0.0071413629 | R12: CUST-0006 | S12: =INDEX(TransactionTable[State],MATCH(R12,TransactionTable[Customer_ID],0)) -> Lagos | T12: =INDEX(TransactionTable[Account_Type],MATCH(R12,TransactionTable[Customer_ID],0)) -> Current | U12: =SUMIFS(TransactionTable[Amount],TransactionTable[Customer_ID],R12) -> 247545.09 | V12: =COUNTIF(TransactionTable[Customer_ID],R12) -> 10 | W12: =U12+ROW()/10^7 -> 247545.09
B13: 7 | C13: =INDEX($R$7:$R$356,MATCH(LARGE($W$7:$W$356,B13),$W$7:$W$356,0)) -> CUST-0257 | D13: =INDEX($S$7:$S$356,MATCH(LARGE($W$7:$W$356,B13),$W$7:$W$356,0)) -> Ogun | E13: =INDEX($T$7:$T$356,MATCH(LARGE($W$7:$W$356,B13),$W$7:$W$356,0)) -> Savings | F13: =INDEX($U$7:$U$356,MATCH(LARGE($W$7:$W$356,B13),$W$7:$W$356,0)) -> 258224.21 | G13: =INDEX($V$7:$V$356,MATCH(LARGE($W$7:$W$356,B13),$W$7:$W$356,0)) -> 16 | H13: =F13/SUM(TransactionTable[Amount]) -> 0.0069859729 | R13: CUST-0007 | S13: =INDEX(TransactionTable[State],MATCH(R13,TransactionTable[Customer_ID],0)) -> Lagos | T13: =INDEX(TransactionTable[Account_Type],MATCH(R13,TransactionTable[Customer_ID],0)) -> Current | U13: =SUMIFS(TransactionTable[Amount],TransactionTable[Customer_ID],R13) -> 103999.78 | V13: =COUNTIF(TransactionTable[Customer_ID],R13) -> 7 | W13: =U13+ROW()/10^7 -> 103999.78
B14: 8 | C14: =INDEX($R$7:$R$356,MATCH(LARGE($W$7:$W$356,B14),$W$7:$W$356,0)) -> CUST-0168 | D14: =INDEX($S$7:$S$356,MATCH(LARGE($W$7:$W$356,B14),$W$7:$W$356,0)) -> Lagos | E14: =INDEX($T$7:$T$356,MATCH(LARGE($W$7:$W$356,B14),$W$7:$W$356,0)) -> Tier 1 Wallet | F14: =INDEX($U$7:$U$356,MATCH(LARGE($W$7:$W$356,B14),$W$7:$W$356,0)) -> 257489.54 | G14: =INDEX($V$7:$V$356,MATCH(LARGE($W$7:$W$356,B14),$W$7:$W$356,0)) -> 10 | H14: =F14/SUM(TransactionTable[Amount]) -> 0.0069660972 | R14: CUST-0008 | S14: =INDEX(TransactionTable[State],MATCH(R14,TransactionTable[Customer_ID],0)) -> Lagos | T14: =INDEX(TransactionTable[Account_Type],MATCH(R14,TransactionTable[Customer_ID],0)) -> Savings | U14: =SUMIFS(TransactionTable[Amount],TransactionTable[Customer_ID],R14) -> 17482.99 | V14: =COUNTIF(TransactionTable[Customer_ID],R14) -> 3 | W14: =U14+ROW()/10^7 -> 17482.99
B15: 9 | C15: =INDEX($R$7:$R$356,MATCH(LARGE($W$7:$W$356,B15),$W$7:$W$356,0)) -> CUST-0006 | D15: =INDEX($S$7:$S$356,MATCH(LARGE($W$7:$W$356,B15),$W$7:$W$356,0)) -> Lagos | E15: =INDEX($T$7:$T$356,MATCH(LARGE($W$7:$W$356,B15),$W$7:$W$356,0)) -> Current | F15: =INDEX($U$7:$U$356,MATCH(LARGE($W$7:$W$356,B15),$W$7:$W$356,0)) -> 247545.09 | G15: =INDEX($V$7:$V$356,MATCH(LARGE($W$7:$W$356,B15),$W$7:$W$356,0)) -> 10 | H15: =F15/SUM(TransactionTable[Amount]) -> 0.006697061 | R15: CUST-0009 | S15: =INDEX(TransactionTable[State],MATCH(R15,TransactionTable[Customer_ID],0)) -> Kaduna | T15: =INDEX(TransactionTable[Account_Type],MATCH(R15,TransactionTable[Customer_ID],0)) -> Savings | U15: =SUMIFS(TransactionTable[Amount],TransactionTable[Customer_ID],R15) -> 88877.39 | V15: =COUNTIF(TransactionTable[Customer_ID],R15) -> 6 | W15: =U15+ROW()/10^7 -> 88877.39
B16: 10 | C16: =INDEX($R$7:$R$356,MATCH(LARGE($W$7:$W$356,B16),$W$7:$W$356,0)) -> CUST-0275 | D16: =INDEX($S$7:$S$356,MATCH(LARGE($W$7:$W$356,B16),$W$7:$W$356,0)) -> Kano | E16: =INDEX($T$7:$T$356,MATCH(LARGE($W$7:$W$356,B16),$W$7:$W$356,0)) -> Current | F16: =INDEX($U$7:$U$356,MATCH(LARGE($W$7:$W$356,B16),$W$7:$W$356,0)) -> 247160.95 | G16: =INDEX($V$7:$V$356,MATCH(LARGE($W$7:$W$356,B16),$W$7:$W$356,0)) -> 11 | H16: =F16/SUM(TransactionTable[Amount]) -> 0.0066866685 | R16: CUST-0010 | S16: =INDEX(TransactionTable[State],MATCH(R16,TransactionTable[Customer_ID],0)) -> Oyo | T16: =INDEX(TransactionTable[Account_Type],MATCH(R16,TransactionTable[Customer_ID],0)) -> Savings | U16: =SUMIFS(TransactionTable[Amount],TransactionTable[Customer_ID],R16) -> 159383.87 | V16: =COUNTIF(TransactionTable[Customer_ID],R16) -> 10 | W16: =U16+ROW()/10^7 -> 159383.87
B17: Top 10 | F17: =SUM(F7:F16) -> 2866642 | G17: =SUM(G7:G16) -> 101 | H17: =SUM(H7:H16) -> 0.077553856 | R17: CUST-0011 | S17: =INDEX(TransactionTable[State],MATCH(R17,TransactionTable[Customer_ID],0)) -> Lagos | T17: =INDEX(TransactionTable[Account_Type],MATCH(R17,TransactionTable[Customer_ID],0)) -> Savings | U17: =SUMIFS(TransactionTable[Amount],TransactionTable[Customer_ID],R17) -> 201268.14 | V17: =COUNTIF(TransactionTable[Customer_ID],R17) -> 13 | W17: =U17+ROW()/10^7 -> 201268.14
B18: Total Spent = cumulative value of all transactions initiated by the customer (all statuses), consistent with platform Total Transaction Value. | R18: CUST-0012 | S18: =INDEX(TransactionTable[State],MATCH(R18,TransactionTable[Customer_ID],0)) -> Edo | T18: =INDEX(TransactionTable[Account_Type],MATCH(R18,TransactionTable[Customer_ID],0)) -> Tier 1 Wallet | U18: =SUMIFS(TransactionTable[Amount],TransactionTable[Customer_ID],R18) -> 129369.67 | V18: =COUNTIF(TransactionTable[Customer_ID],R18) -> 8 | W18: =U18+ROW()/10^7 -> 129369.67
R19: CUST-0013 | S19: =INDEX(TransactionTable[State],MATCH(R19,TransactionTable[Customer_ID],0)) -> Lagos | T19: =INDEX(TransactionTable[Account_Type],MATCH(R19,TransactionTable[Customer_ID],0)) -> Current | U19: =SUMIFS(TransactionTable[Amount],TransactionTable[Customer_ID],R19) -> 7652.34 | V19: =COUNTIF(TransactionTable[Customer_ID],R19) -> 2 | W19: =U19+ROW()/10^7 -> 7652.34
R20: CUST-0014 | S20: =INDEX(TransactionTable[State],MATCH(R20,TransactionTable[Customer_ID],0)) -> Lagos | T20: =INDEX(TransactionTable[Account_Type],MATCH(R20,TransactionTable[Customer_ID],0)) -> Savings | U20: =SUMIFS(TransactionTable[Amount],TransactionTable[Customer_ID],R20) -> 222343.95 | V20: =COUNTIF(TransactionTable[Customer_ID],R20) -> 17 | W20: =U20+ROW()/10^7 -> 222343.95
B21: DEMOGRAPHIC ANALYSIS · BY ACCOUNT TYPE | R21: CUST-0015 | S21: =INDEX(TransactionTable[State],MATCH(R21,TransactionTable[Customer_ID],0)) -> Enugu | T21: =INDEX(TransactionTable[Account_Type],MATCH(R21,TransactionTable[Customer_ID],0)) -> Savings | U21: =SUMIFS(TransactionTable[Amount],TransactionTable[Customer_ID],R21) -> 14487.74 | V21: =COUNTIF(TransactionTable[Customer_ID],R21) -> 2 | W21: =U21+ROW()/10^7 -> 14487.74
B22: Account_Type | C22: Unique Customers | D22: Transaction Count | E22: Total Value (₦) | F22: Avg Transaction Value (₦) | G22: % of Value | R22: CUST-0016 | S22: =INDEX(TransactionTable[State],MATCH(R22,TransactionTable[Customer_ID],0)) -> Lagos | T22: =INDEX(TransactionTable[Account_Type],MATCH(R22,TransactionTable[Customer_ID],0)) -> Current | U22: =SUMIFS(TransactionTable[Amount],TransactionTable[Customer_ID],R22) -> 57390.95 | V22: =COUNTIF(TransactionTable[Customer_ID],R22) -> 10 | W22: =U22+ROW()/10^7 -> 57390.95
B23: Savings | C23: =COUNTIF($T$7:$T$356,B23) -> 181 | D23: =COUNTIF(TransactionTable[Account_Type],B23) -> 1265 | E23: =SUMIF(TransactionTable[Account_Type],B23,TransactionTable[Amount]) -> 18475808 | F23: =IFERROR(AVERAGEIF(TransactionTable[Account_Type],B23,TransactionTable[Amount]),0) -> 14605.382 | G23: =E23/SUM(TransactionTable[Amount]) -> 0.49984273 | R23: CUST-0017 | S23: =INDEX(TransactionTable[State],MATCH(R23,TransactionTable[Customer_ID],0)) -> Lagos | T23: =INDEX(TransactionTable[Account_Type],MATCH(R23,TransactionTable[Customer_ID],0)) -> Tier 3 Verified | U23: =SUMIFS(TransactionTable[Amount],TransactionTable[Customer_ID],R23) -> 164629.67 | V23: =COUNTIF(TransactionTable[Customer_ID],R23) -> 7 | W23: =U23+ROW()/10^7 -> 164629.67
B24: Current | C24: =COUNTIF($T$7:$T$356,B24) -> 72 | D24: =COUNTIF(TransactionTable[Account_Type],B24) -> 551 | E24: =SUMIF(TransactionTable[Account_Type],B24,TransactionTable[Amount]) -> 7926946.6 | F24: =IFERROR(AVERAGEIF(TransactionTable[Account_Type],B24,TransactionTable[Amount]),0) -> 14386.473 | G24: =E24/SUM(TransactionTable[Amount]) -> 0.21445485 | R24: CUST-0018 | S24: =INDEX(TransactionTable[State],MATCH(R24,TransactionTable[Customer_ID],0)) -> Delta | T24: =INDEX(TransactionTable[Account_Type],MATCH(R24,TransactionTable[Customer_ID],0)) -> Tier 1 Wallet | U24: =SUMIFS(TransactionTable[Amount],TransactionTable[Customer_ID],R24) -> 88948.92 | V24: =COUNTIF(TransactionTable[Customer_ID],R24) -> 6 | W24: =U24+ROW()/10^7 -> 88948.92
B25: Tier 1 Wallet | C25: =COUNTIF($T$7:$T$356,B25) -> 65 | D25: =COUNTIF(TransactionTable[Account_Type],B25) -> 457 | E25: =SUMIF(TransactionTable[Account_Type],B25,TransactionTable[Amount]) -> 7113532.1 | F25: =IFERROR(AVERAGEIF(TransactionTable[Account_Type],B25,TransactionTable[Amount]),0) -> 15565.716 | G25: =E25/SUM(TransactionTable[Amount]) -> 0.19244881 | R25: CUST-0019 | S25: =INDEX(TransactionTable[State],MATCH(R25,TransactionTable[Customer_ID],0)) -> Delta | T25: =INDEX(TransactionTable[Account_Type],MATCH(R25,TransactionTable[Customer_ID],0)) -> Savings | U25: =SUMIFS(TransactionTable[Amount],TransactionTable[Customer_ID],R25) -> 74919.28 | V25: =COUNTIF(TransactionTable[Customer_ID],R25) -> 5 | W25: =U25+ROW()/10^7 -> 74919.28
B26: Tier 3 Verified | C26: =COUNTIF($T$7:$T$356,B26) -> 32 | D26: =COUNTIF(TransactionTable[Account_Type],B26) -> 227 | E26: =SUMIF(TransactionTable[Account_Type],B26,TransactionTable[Amount]) -> 3446955.7 | F26: =IFERROR(AVERAGEIF(TransactionTable[Account_Type],B26,TransactionTable[Amount]),0) -> 15184.827 | G26: =E26/SUM(TransactionTable[Amount]) -> 0.093253607 | R26: CUST-0020 | S26: =INDEX(TransactionTable[State],MATCH(R26,TransactionTable[Customer_ID],0)) -> Lagos | T26: =INDEX(TransactionTable[Account_Type],MATCH(R26,TransactionTable[Customer_ID],0)) -> Savings | U26: =SUMIFS(TransactionTable[Amount],TransactionTable[Customer_ID],R26) -> 164477.71 | V26: =COUNTIF(TransactionTable[Customer_ID],R26) -> 11 | W26: =U26+ROW()/10^7 -> 164477.71
B27: Total | C27: =SUM(C23:C26) -> 350 | D27: =SUM(D23:D26) -> 2500 | E27: =SUM(E23:E26) -> 36963243 | F27: =IFERROR(E27/D27,0) -> 14785.297 | G27: =SUM(G23:G26) -> 1 | R27: CUST-0021 | S27: =INDEX(TransactionTable[State],MATCH(R27,TransactionTable[Customer_ID],0)) -> Lagos | T27: =INDEX(TransactionTable[Account_Type],MATCH(R27,TransactionTable[Customer_ID],0)) -> Tier 1 Wallet | U27: =SUMIFS(TransactionTable[Amount],TransactionTable[Customer_ID],R27) -> 127385.9 | V27: =COUNTIF(TransactionTable[Customer_ID],R27) -> 11 | W27: =U27+ROW()/10^7 -> 127385.9
R28: CUST-0022 | S28: =INDEX(TransactionTable[State],MATCH(R28,TransactionTable[Customer_ID],0)) -> Lagos | T28: =INDEX(TransactionTable[Account_Type],MATCH(R28,TransactionTable[Customer_ID],0)) -> Current | U28: =SUMIFS(TransactionTable[Amount],TransactionTable[Customer_ID],R28) -> 110345.6 | V28: =COUNTIF(TransactionTable[Customer_ID],R28) -> 7 | W28: =U28+ROW()/10^7 -> 110345.6
R29: CUST-0023 | S29: =INDEX(TransactionTable[State],MATCH(R29,TransactionTable[Customer_ID],0)) -> Kaduna | T29: =INDEX(TransactionTable[Account_Type],MATCH(R29,TransactionTable[Customer_ID],0)) -> Savings | U29: =SUMIFS(TransactionTable[Amount],TransactionTable[Customer_ID],R29) -> 189351.95 | V29: =COUNTIF(TransactionTable[Customer_ID],R29) -> 6 | W29: =U29+ROW()/10^7 -> 189351.95
B30: DEMOGRAPHIC ANALYSIS · BY CUSTOMER AGE GROUP | R30: CUST-0024 | S30: =INDEX(TransactionTable[State],MATCH(R30,TransactionTable[Customer_ID],0)) -> Kaduna | T30: =INDEX(TransactionTable[Account_Type],MATCH(R30,TransactionTable[Customer_ID],0)) -> Savings | U30: =SUMIFS(TransactionTable[Amount],TransactionTable[Customer_ID],R30) -> 186366.17 | V30: =COUNTIF(TransactionTable[Customer_ID],R30) -> 7 | W30: =U30+ROW()/10^7 -> 186366.17
B31: Age Group | C31: Age From | D31: Age To | E31: Transaction Count | F31: Total Value (₦) | G31: Avg Transaction Value (₦) | H31: % of Value | R31: CUST-0025 | S31: =INDEX(TransactionTable[State],MATCH(R31,TransactionTable[Customer_ID],0)) -> Kaduna | T31: =INDEX(TransactionTable[Account_Type],MATCH(R31,TransactionTable[Customer_ID],0)) -> Tier 1 Wallet | U31: =SUMIFS(TransactionTable[Amount],TransactionTable[Customer_ID],R31) -> 159098.05 | V31: =COUNTIF(TransactionTable[Customer_ID],R31) -> 6 | W31: =U31+ROW()/10^7 -> 159098.05
B32: <25 | C32: 0 | D32: 24 | E32: =COUNTIFS(TransactionTable[Customer_Age],">="&C32,TransactionTable[Customer_Age],"<="&D32) -> 197 | F32: =SUMIFS(TransactionTable[Amount],TransactionTable[Customer_Age],">="&C32,TransactionTable[Customer_Age],"<="&D32) -> 2916156.3 | G32: =IFERROR(F32/E32,0) -> 14802.824 | H32: =F32/SUM(TransactionTable[Amount]) -> 0.07889341 | R32: CUST-0026 | S32: =INDEX(TransactionTable[State],MATCH(R32,TransactionTable[Customer_ID],0)) -> Kaduna | T32: =INDEX(TransactionTable[Account_Type],MATCH(R32,TransactionTable[Customer_ID],0)) -> Savings | U32: =SUMIFS(TransactionTable[Amount],TransactionTable[Customer_ID],R32) -> 124809.19 | V32: =COUNTIF(TransactionTable[Customer_ID],R32) -> 6 | W32: =U32+ROW()/10^7 -> 124809.19
B33: 25-34 | C33: 25 | D33: 34 | E33: =COUNTIFS(TransactionTable[Customer_Age],">="&C33,TransactionTable[Customer_Age],"<="&D33) -> 934 | F33: =SUMIFS(TransactionTable[Amount],TransactionTable[Customer_Age],">="&C33,TransactionTable[Customer_Age],"<="&D33) -> 12580844 | G33: =IFERROR(F33/E33,0) -> 13469.855 | H33: =F33/SUM(TransactionTable[Amount]) -> 0.34036095 | R33: CUST-0027 | S33: =INDEX(TransactionTable[State],MATCH(R33,TransactionTable[Customer_ID],0)) -> Lagos | T33: =INDEX(TransactionTable[Account_Type],MATCH(R33,TransactionTable[Customer_ID],0)) -> Tier 1 Wallet | U33: =SUMIFS(TransactionTable[Amount],TransactionTable[Customer_ID],R33) -> 72092.19 | V33: =COUNTIF(TransactionTable[Customer_ID],R33) -> 7 | W33: =U33+ROW()/10^7 -> 72092.19
B34: 35-49 | C34: 35 | D34: 49 | E34: =COUNTIFS(TransactionTable[Customer_Age],">="&C34,TransactionTable[Customer_Age],"<="&D34) -> 994 | F34: =SUMIFS(TransactionTable[Amount],TransactionTable[Customer_Age],">="&C34,TransactionTable[Customer_Age],"<="&D34) -> 16058522 | G34: =IFERROR(F34/E34,0) -> 16155.455 | H34: =F34/SUM(TransactionTable[Amount]) -> 0.43444572 | R34: CUST-0028 | S34: =INDEX(TransactionTable[State],MATCH(R34,TransactionTable[Customer_ID],0)) -> Lagos | T34: =INDEX(TransactionTable[Account_Type],MATCH(R34,TransactionTable[Customer_ID],0)) -> Savings | U34: =SUMIFS(TransactionTable[Amount],TransactionTable[Customer_ID],R34) -> 117759.07 | V34: =COUNTIF(TransactionTable[Customer_ID],R34) -> 6 | W34: =U34+ROW()/10^7 -> 117759.07
B35: 50+ | C35: 50 | D35: 150 | E35: =COUNTIFS(TransactionTable[Customer_Age],">="&C35,TransactionTable[Customer_Age],"<="&D35) -> 375 | F35: =SUMIFS(TransactionTable[Amount],TransactionTable[Customer_Age],">="&C35,TransactionTable[Customer_Age],"<="&D35) -> 5407719.7 | G35: =IFERROR(F35/E35,0) -> 14420.586 | H35: =F35/SUM(TransactionTable[Amount]) -> 0.14629993 | R35: CUST-0029 | S35: =INDEX(TransactionTable[State],MATCH(R35,TransactionTable[Customer_ID],0)) -> Lagos | T35: =INDEX(TransactionTable[Account_Type],MATCH(R35,TransactionTable[Customer_ID],0)) -> Tier 1 Wallet | U35: =SUMIFS(TransactionTable[Amount],TransactionTable[Customer_ID],R35) -> 29132.73 | V35: =COUNTIF(TransactionTable[Customer_ID],R35) -> 3 | W35: =U35+ROW()/10^7 -> 29132.73
B36: Total | E36: =SUM(E32:E35) -> 2500 | F36: =SUM(F32:F35) -> 36963243 | G36: =IFERROR(F36/E36,0) -> 14785.297 | H36: =SUM(H32:H35) -> 1 | R36: CUST-0030 | S36: =INDEX(TransactionTable[State],MATCH(R36,TransactionTable[Customer_ID],0)) -> Enugu | T36: =INDEX(TransactionTable[Account_Type],MATCH(R36,TransactionTable[Customer_ID],0)) -> Savings | U36: =SUMIFS(TransactionTable[Amount],TransactionTable[Customer_ID],R36) -> 170030.9 | V36: =COUNTIF(TransactionTable[Customer_ID],R36) -> 10 | W36: =U36+ROW()/10^7 -> 170030.9
B37: Age band boundaries (blue) are analyst-defined inputs per brief: <25, 25-34, 35-49, 50+. Edit to re-band; all figures recalculate. | R37: CUST-0031 | S37: =INDEX(TransactionTable[State],MATCH(R37,TransactionTable[Customer_ID],0)) -> FCT Abuja | T37: =INDEX(TransactionTable[Account_Type],MATCH(R37,TransactionTable[Customer_ID],0)) -> Tier 1 Wallet | U37: =SUMIFS(TransactionTable[Amount],TransactionTable[Customer_ID],R37) -> 197724.77 | V37: =COUNTIF(TransactionTable[Customer_ID],R37) -> 8 | W37: =U37+ROW()/10^7 -> 197724.77
R38: CUST-0032 | S38: =INDEX(TransactionTable[State],MATCH(R38,TransactionTable[Customer_ID],0)) -> Kaduna | T38: =INDEX(TransactionTable[Account_Type],MATCH(R38,TransactionTable[Customer_ID],0)) -> Savings | U38: =SUMIFS(TransactionTable[Amount],TransactionTable[Customer_ID],R38) -> 111237.24 | V38: =COUNTIF(TransactionTable[Customer_ID],R38) -> 6 | W38: =U38+ROW()/10^7 -> 111237.24
R39: CUST-0033 | S39: =INDEX(TransactionTable[State],MATCH(R39,TransactionTable[Customer_ID],0)) -> Kano | T39: =INDEX(TransactionTable[Account_Type],MATCH(R39,TransactionTable[Customer_ID],0)) -> Savings | U39: =SUMIFS(TransactionTable[Amount],TransactionTable[Customer_ID],R39) -> 125937.75 | V39: =COUNTIF(TransactionTable[Customer_ID],R39) -> 4 | W39: =U39+ROW()/10^7 -> 125937.75
R40: CUST-0034 | S40: =INDEX(TransactionTable[State],MATCH(R40,TransactionTable[Customer_ID],0)) -> Lagos | T40: =INDEX(TransactionTable[Account_Type],MATCH(R40,TransactionTable[Customer_ID],0)) -> Current | U40: =SUMIFS(TransactionTable[Amount],TransactionTable[Customer_ID],R40) -> 349166.65 | V40: =COUNTIF(TransactionTable[Customer_ID],R40) -> 10 | W40: =U40+ROW()/10^7 -> 349166.65
R41: CUST-0035 | S41: =INDEX(TransactionTable[State],MATCH(R41,TransactionTable[Customer_ID],0)) -> Rivers | T41: =INDEX(TransactionTable[Account_Type],MATCH(R41,TransactionTable[Customer_ID],0)) -> Tier 3 Verified | U41: =SUMIFS(TransactionTable[Amount],TransactionTable[Customer_ID],R41) -> 72466.84 | V41: =COUNTIF(TransactionTable[Customer_ID],R41) -> 10 | W41: =U41+ROW()/10^7 -> 72466.84
R42: CUST-0036 | S42: =INDEX(TransactionTable[State],MATCH(R42,TransactionTable[Customer_ID],0)) -> Kano | T42: =INDEX(TransactionTable[Account_Type],MATCH(R42,TransactionTable[Customer_ID],0)) -> Tier 1 Wallet | U42: =SUMIFS(TransactionTable[Amount],TransactionTable[Customer_ID],R42) -> 72582.75 | V42: =COUNTIF(TransactionTable[Customer_ID],R42) -> 4 | W42: =U42+ROW()/10^7 -> 72582.75
...

Sheet Obj3_Product_Popularity
B2: OBJECTIVE 3 · PRODUCT & PAYMENT CHANNEL POPULARITY
B3: Core questions: Which transaction types and payment methods dominate transaction counts vs value?
B5: PRODUCT MATRIX · TRANSACTION TYPE
B6: Transaction Type | C6: Volume | D6: % of Volume | E6: Total Value (₦) | F6: Average Ticket Size (₦) | G6: % Value Contribution | H6: Volume Rank | I6: Value Rank
B7: Transfer | C7: =COUNTIF(TransactionTable[Transaction_Type],B7) -> 1085 | D7: =C7/$C$12 -> 0.434 | E7: =SUMIF(TransactionTable[Transaction_Type],B7,TransactionTable[Amount]) -> 27884107 | F7: =IFERROR(AVERAGEIF(TransactionTable[Transaction_Type],B7,TransactionTable[Amount]),0) -> 25699.638 | G7: =E7/$E$12 -> 0.75437394 | H7: =RANK(C7,$C$7:$C$11) -> 1 | I7: =RANK(E7,$E$7:$E$11) -> 1
B8: Airtime/Data | C8: =COUNTIF(TransactionTable[Transaction_Type],B8) -> 660 | D8: =C8/$C$12 -> 0.264 | E8: =SUMIF(TransactionTable[Transaction_Type],B8,TransactionTable[Amount]) -> 1133662.3 | F8: =IFERROR(AVERAGEIF(TransactionTable[Transaction_Type],B8,TransactionTable[Amount]),0) -> 1717.6701 | G8: =E8/$E$12 -> 0.03066999 | H8: =RANK(C8,$C$7:$C$11) -> 2 | I8: =RANK(E8,$E$7:$E$11) -> 5
B9: Bill Payment | C9: =COUNTIF(TransactionTable[Transaction_Type],B9) -> 377 | D9: =C9/$C$12 -> 0.1508 | E9: =SUMIF(TransactionTable[Transaction_Type],B9,TransactionTable[Amount]) -> 4243869.8 | F9: =IFERROR(AVERAGEIF(TransactionTable[Transaction_Type],B9,TransactionTable[Amount]),0) -> 11256.949 | G9: =E9/$E$12 -> 0.11481325 | H9: =RANK(C9,$C$7:$C$11) -> 3 | I9: =RANK(E9,$E$7:$E$11) -> 2
B10: POS Payment | C10: =COUNTIF(TransactionTable[Transaction_Type],B10) -> 268 | D10: =C10/$C$12 -> 0.1072 | E10: =SUMIF(TransactionTable[Transaction_Type],B10,TransactionTable[Amount]) -> 2171603.6 | F10: =IFERROR(AVERAGEIF(TransactionTable[Transaction_Type],B10,TransactionTable[Amount]),0) -> 8102.9986 | G10: =E10/$E$12 -> 0.058750355 | H10: =RANK(C10,$C$7:$C$11) -> 4 | I10: =RANK(E10,$E$7:$E$11) -> 3
B11: Card Withdrawal | C11: =COUNTIF(TransactionTable[Transaction_Type],B11) -> 110 | D11: =C11/$C$12 -> 0.044 | E11: =SUMIF(TransactionTable[Transaction_Type],B11,TransactionTable[Amount]) -> 1530000 | F11: =IFERROR(AVERAGEIF(TransactionTable[Transaction_Type],B11,TransactionTable[Amount]),0) -> 13909.091 | G11: =E11/$E$12 -> 0.041392472 | H11: =RANK(C11,$C$7:$C$11) -> 5 | I11: =RANK(E11,$E$7:$E$11) -> 4
B12: Total | C12: =SUM(C7:C11) -> 2500 | D12: =SUM(D7:D11) -> 1 | E12: =SUM(E7:E11) -> 36963243 | F12: =IFERROR(E12/C12,0) -> 14785.297 | G12: =SUM(G7:G11) -> 1
B13: 'POS' in the brief maps to the source label 'POS Payment'.
B16: PAYMENT CHANNEL · VOLUME & VALUE BY PAYMENT METHOD
B17: Payment Method | C17: Volume | D17: % of Volume | E17: Total Value (₦) | F17: Average Ticket Size (₦) | G17: % Value Contribution | H17: Volume Rank | I17: Value Rank
B18: Bank Transfer | C18: =COUNTIF(TransactionTable[Payment_Method],B18) -> 1251 | D18: =C18/$C$22 -> 0.5004 | E18: =SUMIF(TransactionTable[Payment_Method],B18,TransactionTable[Amount]) -> 18382632 | F18: =IFERROR(AVERAGEIF(TransactionTable[Payment_Method],B18,TransactionTable[Amount]),0) -> 14694.35 | G18: =E18/$E$22 -> 0.49732194 | H18: =RANK(C18,$C$18:$C$21) -> 1 | I18: =RANK(E18,$E$18:$E$21) -> 1
B19: Debit Card | C19: =COUNTIF(TransactionTable[Payment_Method],B19) -> 646 | D19: =C19/$C$22 -> 0.2584 | E19: =SUMIF(TransactionTable[Payment_Method],B19,TransactionTable[Amount]) -> 8882524.9 | F19: =IFERROR(AVERAGEIF(TransactionTable[Payment_Method],B19,TransactionTable[Amount]),0) -> 13750.039 | G19: =E19/$E$22 -> 0.24030697 | H19: =RANK(C19,$C$18:$C$21) -> 2 | I19: =RANK(E19,$E$18:$E$21) -> 2
B20: USSD | C20: =COUNTIF(TransactionTable[Payment_Method],B20) -> 364 | D20: =C20/$C$22 -> 0.1456 | E20: =SUMIF(TransactionTable[Payment_Method],B20,TransactionTable[Amount]) -> 5879513.8 | F20: =IFERROR(AVERAGEIF(TransactionTable[Payment_Method],B20,TransactionTable[Amount]),0) -> 16152.511 | G20: =E20/$E$22 -> 0.1590638 | H20: =RANK(C20,$C$18:$C$21) -> 3 | I20: =RANK(E20,$E$18:$E$21) -> 3
B21: Wallet Balance | C21: =COUNTIF(TransactionTable[Payment_Method],B21) -> 239 | D21: =C21/$C$22 -> 0.0956 | E21: =SUMIF(TransactionTable[Payment_Method],B21,TransactionTable[Amount]) -> 3818572.2 | F21: =IFERROR(AVERAGEIF(TransactionTable[Payment_Method],B21,TransactionTable[Amount]),0) -> 15977.29 | G21: =E21/$E$22 -> 0.10330728 | H21: =RANK(C21,$C$18:$C$21) -> 4 | I21: =RANK(E21,$E$18:$E$21) -> 4
B22: Total | C22: =SUM(C18:C21) -> 2500 | D22: =SUM(D18:D21) -> 1 | E22: =SUM(E18:E21) -> 36963243 | F22: =IFERROR(E22/C22,0) -> 14785.297 | G22: =SUM(G18:G21) -> 1

Sheet Obj4_Geographic_Distribution
B2: OBJECTIVE 4 · GEOGRAPHIC DISTRIBUTION
B3: Core questions: Which Nigerian states exhibit the highest transaction activity and revenue?
B5: STATE PERFORMANCE · RANKED BY TOTAL REVENUE | S5: STATE LEDGER (supporting calc) | X5: Chart helper (splits ranked revenue into hub / other so hub bars stay highlighted after re-ranking)
B6: Rank | C6: State | D6: Total Revenue (₦) | E6: Transaction Count | F6: Average Value (₦) | G6: % of Revenue | H6: Regional Hub | S6: State | T6: Total Revenue (₦) | U6: Txn Count | V6: Rank Key (tie-break) | X6: Chart: Key Hub | Y6: Chart: Other State
B7: 1 | C7: =INDEX($S$7:$S$16,MATCH(LARGE($V$7:$V$16,B7),$V$7:$V$16,0)) -> Lagos | D7: =INDEX($T$7:$T$16,MATCH(LARGE($V$7:$V$16,B7),$V$7:$V$16,0)) -> 14255387 | E7: =INDEX($U$7:$U$16,MATCH(LARGE($V$7:$V$16,B7),$V$7:$V$16,0)) -> 985 | F7: =IFERROR(D7/E7,0) -> 14472.474 | G7: =D7/SUM(TransactionTable[Amount]) -> 0.38566386 | H7: =IF(OR(C7="Lagos",C7="FCT Abuja",C7="Rivers"),"★ Key Hub","") -> ★ Key Hub | S7: Delta | T7: =SUMIF(TransactionTable[State],S7,TransactionTable[Amount]) -> 2519131.7 | U7: =COUNTIF(TransactionTable[State],S7) -> 150 | V7: =T7+ROW()/10^7 -> 2519131.7 | X7: =IF($H7<>"",$D7,0) -> 14255387 | Y7: =IF($H7="",$D7,0) -> 0
B8: 2 | C8: =INDEX($S$7:$S$16,MATCH(LARGE($V$7:$V$16,B8),$V$7:$V$16,0)) -> Kano | D8: =INDEX($T$7:$T$16,MATCH(LARGE($V$7:$V$16,B8),$V$7:$V$16,0)) -> 4166745.1 | E8: =INDEX($U$7:$U$16,MATCH(LARGE($V$7:$V$16,B8),$V$7:$V$16,0)) -> 266 | F8: =IFERROR(D8/E8,0) -> 15664.455 | G8: =D8/SUM(TransactionTable[Amount]) -> 0.11272672 | H8: =IF(OR(C8="Lagos",C8="FCT Abuja",C8="Rivers"),"★ Key Hub","") | S8: Edo | T8: =SUMIF(TransactionTable[State],S8,TransactionTable[Amount]) -> 1595024.6 | U8: =COUNTIF(TransactionTable[State],S8) -> 101 | V8: =T8+ROW()/10^7 -> 1595024.6 | X8: =IF($H8<>"",$D8,0) -> 0 | Y8: =IF($H8="",$D8,0) -> 4166745.1
B9: 3 | C9: =INDEX($S$7:$S$16,MATCH(LARGE($V$7:$V$16,B9),$V$7:$V$16,0)) -> Oyo | D9: =INDEX($T$7:$T$16,MATCH(LARGE($V$7:$V$16,B9),$V$7:$V$16,0)) -> 3305333.8 | E9: =INDEX($U$7:$U$16,MATCH(LARGE($V$7:$V$16,B9),$V$7:$V$16,0)) -> 253 | F9: =IFERROR(D9/E9,0) -> 13064.561 | G9: =D9/SUM(TransactionTable[Amount]) -> 0.089422182 | H9: =IF(OR(C9="Lagos",C9="FCT Abuja",C9="Rivers"),"★ Key Hub","") | S9: Enugu | T9: =SUMIF(TransactionTable[State],S9,TransactionTable[Amount]) -> 1254513.3 | U9: =COUNTIF(TransactionTable[State],S9) -> 92 | V9: =T9+ROW()/10^7 -> 1254513.3 | X9: =IF($H9<>"",$D9,0) -> 0 | Y9: =IF($H9="",$D9,0) -> 3305333.8
B10: 4 | C10: =INDEX($S$7:$S$16,MATCH(LARGE($V$7:$V$16,B10),$V$7:$V$16,0)) -> FCT Abuja | D10: =INDEX($T$7:$T$16,MATCH(LARGE($V$7:$V$16,B10),$V$7:$V$16,0)) -> 3304556.5 | E10: =INDEX($U$7:$U$16,MATCH(LARGE($V$7:$V$16,B10),$V$7:$V$16,0)) -> 250 | F10: =IFERROR(D10/E10,0) -> 13218.226 | G10: =D10/SUM(TransactionTable[Amount]) -> 0.089401152 | H10: =IF(OR(C10="Lagos",C10="FCT Abuja",C10="Rivers"),"★ Key Hub","") -> ★ Key Hub | S10: FCT Abuja | T10: =SUMIF(TransactionTable[State],S10,TransactionTable[Amount]) -> 3304556.5 | U10: =COUNTIF(TransactionTable[State],S10) -> 250 | V10: =T10+ROW()/10^7 -> 3304556.5 | X10: =IF($H10<>"",$D10,0) -> 3304556.5 | Y10: =IF($H10="",$D10,0) -> 0
B11: 5 | C11: =INDEX($S$7:$S$16,MATCH(LARGE($V$7:$V$16,B11),$V$7:$V$16,0)) -> Rivers | D11: =INDEX($T$7:$T$16,MATCH(LARGE($V$7:$V$16,B11),$V$7:$V$16,0)) -> 2910052.3 | E11: =INDEX($U$7:$U$16,MATCH(LARGE($V$7:$V$16,B11),$V$7:$V$16,0)) -> 187 | F11: =IFERROR(D11/E11,0) -> 15561.777 | G11: =D11/SUM(TransactionTable[Amount]) -> 0.078728274 | H11: =IF(OR(C11="Lagos",C11="FCT Abuja",C11="Rivers"),"★ Key Hub","") -> ★ Key Hub | S11: Kaduna | T11: =SUMIF(TransactionTable[State],S11,TransactionTable[Amount]) -> 1334629.1 | U11: =COUNTIF(TransactionTable[State],S11) -> 77 | V11: =T11+ROW()/10^7 -> 1334629.1 | X11: =IF($H11<>"",$D11,0) -> 2910052.3 | Y11: =IF($H11="",$D11,0) -> 0
B12: 6 | C12: =INDEX($S$7:$S$16,MATCH(LARGE($V$7:$V$16,B12),$V$7:$V$16,0)) -> Delta | D12: =INDEX($T$7:$T$16,MATCH(LARGE($V$7:$V$16,B12),$V$7:$V$16,0)) -> 2519131.7 | E12: =INDEX($U$7:$U$16,MATCH(LARGE($V$7:$V$16,B12),$V$7:$V$16,0)) -> 150 | F12: =IFERROR(D12/E12,0) -> 16794.212 | G12: =D12/SUM(TransactionTable[Amount]) -> 0.068152347 | H12: =IF(OR(C12="Lagos",C12="FCT Abuja",C12="Rivers"),"★ Key Hub","") | S12: Kano | T12: =SUMIF(TransactionTable[State],S12,TransactionTable[Amount]) -> 4166745.1 | U12: =COUNTIF(TransactionTable[State],S12) -> 266 | V12: =T12+ROW()/10^7 -> 4166745.1 | X12: =IF($H12<>"",$D12,0) -> 0 | Y12: =IF($H12="",$D12,0) -> 2519131.7
B13: 7 | C13: =INDEX($S$7:$S$16,MATCH(LARGE($V$7:$V$16,B13),$V$7:$V$16,0)) -> Ogun | D13: =INDEX($T$7:$T$16,MATCH(LARGE($V$7:$V$16,B13),$V$7:$V$16,0)) -> 2317869.3 | E13: =INDEX($U$7:$U$16,MATCH(LARGE($V$7:$V$16,B13),$V$7:$V$16,0)) -> 139 | F13: =IFERROR(D13/E13,0) -> 16675.318 | G13: =D13/SUM(TransactionTable[Amount]) -> 0.062707412 | H13: =IF(OR(C13="Lagos",C13="FCT Abuja",C13="Rivers"),"★ Key Hub","") | S13: Lagos | T13: =SUMIF(TransactionTable[State],S13,TransactionTable[Amount]) -> 14255387 | U13: =COUNTIF(TransactionTable[State],S13) -> 985 | V13: =T13+ROW()/10^7 -> 14255387 | X13: =IF($H13<>"",$D13,0) -> 0 | Y13: =IF($H13="",$D13,0) -> 2317869.3
B14: 8 | C14: =INDEX($S$7:$S$16,MATCH(LARGE($V$7:$V$16,B14),$V$7:$V$16,0)) -> Edo | D14: =INDEX($T$7:$T$16,MATCH(LARGE($V$7:$V$16,B14),$V$7:$V$16,0)) -> 1595024.6 | E14: =INDEX($U$7:$U$16,MATCH(LARGE($V$7:$V$16,B14),$V$7:$V$16,0)) -> 101 | F14: =IFERROR(D14/E14,0) -> 15792.322 | G14: =D14/SUM(TransactionTable[Amount]) -> 0.043151641 | H14: =IF(OR(C14="Lagos",C14="FCT Abuja",C14="Rivers"),"★ Key Hub","") | S14: Ogun | T14: =SUMIF(TransactionTable[State],S14,TransactionTable[Amount]) -> 2317869.3 | U14: =COUNTIF(TransactionTable[State],S14) -> 139 | V14: =T14+ROW()/10^7 -> 2317869.3 | X14: =IF($H14<>"",$D14,0) -> 0 | Y14: =IF($H14="",$D14,0) -> 1595024.6
B15: 9 | C15: =INDEX($S$7:$S$16,MATCH(LARGE($V$7:$V$16,B15),$V$7:$V$16,0)) -> Kaduna | D15: =INDEX($T$7:$T$16,MATCH(LARGE($V$7:$V$16,B15),$V$7:$V$16,0)) -> 1334629.1 | E15: =INDEX($U$7:$U$16,MATCH(LARGE($V$7:$V$16,B15),$V$7:$V$16,0)) -> 77 | F15: =IFERROR(D15/E15,0) -> 17332.845 | G15: =D15/SUM(TransactionTable[Amount]) -> 0.036106926 | H15: =IF(OR(C15="Lagos",C15="FCT Abuja",C15="Rivers"),"★ Key Hub","") | S15: Oyo | T15: =SUMIF(TransactionTable[State],S15,TransactionTable[Amount]) -> 3305333.8 | U15: =COUNTIF(TransactionTable[State],S15) -> 253 | V15: =T15+ROW()/10^7 -> 3305333.8 | X15: =IF($H15<>"",$D15,0) -> 0 | Y15: =IF($H15="",$D15,0) -> 1334629.1
B16: 10 | C16: =INDEX($S$7:$S$16,MATCH(LARGE($V$7:$V$16,B16),$V$7:$V$16,0)) -> Enugu | D16: =INDEX($T$7:$T$16,MATCH(LARGE($V$7:$V$16,B16),$V$7:$V$16,0)) -> 1254513.3 | E16: =INDEX($U$7:$U$16,MATCH(LARGE($V$7:$V$16,B16),$V$7:$V$16,0)) -> 92 | F16: =IFERROR(D16/E16,0) -> 13636.014 | G16: =D16/SUM(TransactionTable[Amount]) -> 0.033939482 | H16: =IF(OR(C16="Lagos",C16="FCT Abuja",C16="Rivers"),"★ Key Hub","") | S16: Rivers | T16: =SUMIF(TransactionTable[State],S16,TransactionTable[Amount]) -> 2910052.3 | U16: =COUNTIF(TransactionTable[State],S16) -> 187 | V16: =T16+ROW()/10^7 -> 2910052.3 | X16: =IF($H16<>"",$D16,0) -> 0 | Y16: =IF($H16="",$D16,0) -> 1254513.3
B17: Total | D17: =SUM(D7:D16) -> 36963243 | E17: =SUM(E7:E16) -> 2500 | F17: =IFERROR(D17/E17,0) -> 14785.297 | G17: =SUM(G7:G16) -> 1
B18: Shaded rows = key regional hubs (Lagos, FCT Abuja, Rivers). Ranking is formula-driven (LARGE/INDEX/MATCH) and re-sorts automatically.
B20: KEY REGIONAL HUBS · CONCENTRATION
B21: Hub | D21: Total Revenue (₦) | E21: Transaction Count | F21: Average Value (₦) | G21: % of Revenue | H21: % of Volume
B22: Lagos | D22: =SUMIF(TransactionTable[State],B22,TransactionTable[Amount]) -> 14255387 | E22: =COUNTIF(TransactionTable[State],B22) -> 985 | F22: =IFERROR(D22/E22,0) -> 14472.474 | G22: =D22/SUM(TransactionTable[Amount]) -> 0.38566386 | H22: =E22/COUNTA(TransactionTable[Transaction_ID]) -> 0.394
B23: FCT Abuja | D23: =SUMIF(TransactionTable[State],B23,TransactionTable[Amount]) -> 3304556.5 | E23: =COUNTIF(TransactionTable[State],B23) -> 250 | F23: =IFERROR(D23/E23,0) -> 13218.226 | G23: =D23/SUM(TransactionTable[Amount]) -> 0.089401152 | H23: =E23/COUNTA(TransactionTable[Transaction_ID]) -> 0.1
B24: Rivers | D24: =SUMIF(TransactionTable[State],B24,TransactionTable[Amount]) -> 2910052.3 | E24: =COUNTIF(TransactionTable[State],B24) -> 187 | F24: =IFERROR(D24/E24,0) -> 15561.777 | G24: =D24/SUM(TransactionTable[Amount]) -> 0.078728274 | H24: =E24/COUNTA(TransactionTable[Transaction_ID]) -> 0.0748
B25: Combined Key Hubs | D25: =SUM(D22:D24) -> 20469996 | E25: =SUM(E22:E24) -> 1422 | F25: =IFERROR(D25/E25,0) -> 14395.215 | G25: =D25/SUM(TransactionTable[Amount]) -> 0.55379329 | H25: =E25/COUNTA(TransactionTable[Transaction_ID]) -> 0.5688
B26: Other 7 States | D26: =D17-D25 -> 16493247 | E26: =E17-E25 -> 1078 | F26: =IFERROR(D26/E26,0) -> 15299.858 | G26: =D26/SUM(TransactionTable[Amount]) -> 0.44620671 | H26: =E26/COUNTA(TransactionTable[Transaction_ID]) -> 0.4312

Sheet Obj5_Growth_Trajectory
B2: OBJECTIVE 5 · GROWTH TRAJECTORY (JAN – DEC 2025)
B3: Core question: Are overall transaction volumes and values increasing or decreasing month-over-month?
B5: MONTHLY TREND TABLE
B6: Month | C6: Monthly Total Value (₦) | D6: Monthly Volume | E6: MoM Value Growth (%) | F6: MoM Volume Growth (%) | G6: Avg Ticket Size (₦) | H6: Month #
B7: 45658 | C7: =SUMIFS(TransactionTable[Amount],TransactionTable[Transaction_Date],">="&B7,TransactionTable[Transaction_Date],"<"&EDATE(B7,1)) -> 2613872.9 | D7: =COUNTIFS(TransactionTable[Transaction_Date],">="&B7,TransactionTable[Transaction_Date],"<"&EDATE(B7,1)) -> 183 | E7: – | F7: – | G7: =IFERROR(C7/D7,0) -> 14283.458 | H7: 1
B8: =EDATE(B7,1) -> 45689 | C8: =SUMIFS(TransactionTable[Amount],TransactionTable[Transaction_Date],">="&B8,TransactionTable[Transaction_Date],"<"&EDATE(B8,1)) -> 2676223.5 | D8: =COUNTIFS(TransactionTable[Transaction_Date],">="&B8,TransactionTable[Transaction_Date],"<"&EDATE(B8,1)) -> 204 | E8: =IFERROR(C8/C7-1,0) -> 0.023853731 | F8: =IFERROR(D8/D7-1,0) -> 0.1147541 | G8: =IFERROR(C8/D8,0) -> 13118.743 | H8: 2
B9: =EDATE(B8,1) -> 45717 | C9: =SUMIFS(TransactionTable[Amount],TransactionTable[Transaction_Date],">="&B9,TransactionTable[Transaction_Date],"<"&EDATE(B9,1)) -> 3658525.9 | D9: =COUNTIFS(TransactionTable[Transaction_Date],">="&B9,TransactionTable[Transaction_Date],"<"&EDATE(B9,1)) -> 217 | E9: =IFERROR(C9/C8-1,0) -> 0.36704795 | F9: =IFERROR(D9/D8-1,0) -> 0.06372549 | G9: =IFERROR(C9/D9,0) -> 16859.566 | H9: 3
B10: =EDATE(B9,1) -> 45748 | C10: =SUMIFS(TransactionTable[Amount],TransactionTable[Transaction_Date],">="&B10,TransactionTable[Transaction_Date],"<"&EDATE(B10,1)) -> 2410304.2 | D10: =COUNTIFS(TransactionTable[Transaction_Date],">="&B10,TransactionTable[Transaction_Date],"<"&EDATE(B10,1)) -> 184 | E10: =IFERROR(C10/C9-1,0) -> -0.34118158 | F10: =IFERROR(D10/D9-1,0) -> -0.15207373 | G10: =IFERROR(C10/D10,0) -> 13099.48 | H10: 4
B11: =EDATE(B10,1) -> 45778 | C11: =SUMIFS(TransactionTable[Amount],TransactionTable[Transaction_Date],">="&B11,TransactionTable[Transaction_Date],"<"&EDATE(B11,1)) -> 2581277.9 | D11: =COUNTIFS(TransactionTable[Transaction_Date],">="&B11,TransactionTable[Transaction_Date],"<"&EDATE(B11,1)) -> 189 | E11: =IFERROR(C11/C10-1,0) -> 0.070934452 | F11: =IFERROR(D11/D10-1,0) -> 0.027173913 | G11: =IFERROR(C11/D11,0) -> 13657.555 | H11: 5
B12: =EDATE(B11,1) -> 45809 | C12: =SUMIFS(TransactionTable[Amount],TransactionTable[Transaction_Date],">="&B12,TransactionTable[Transaction_Date],"<"&EDATE(B12,1)) -> 4089023.8 | D12: =COUNTIFS(TransactionTable[Transaction_Date],">="&B12,TransactionTable[Transaction_Date],"<"&EDATE(B12,1)) -> 224 | E12: =IFERROR(C12/C11-1,0) -> 0.58410836 | F12: =IFERROR(D12/D11-1,0) -> 0.18518519 | G12: =IFERROR(C12/D12,0) -> 18254.571 | H12: 6
B13: =EDATE(B12,1) -> 45839 | C13: =SUMIFS(TransactionTable[Amount],TransactionTable[Transaction_Date],">="&B13,TransactionTable[Transaction_Date],"<"&EDATE(B13,1)) -> 2958096.9 | D13: =COUNTIFS(TransactionTable[Transaction_Date],">="&B13,TransactionTable[Transaction_Date],"<"&EDATE(B13,1)) -> 207 | E13: =IFERROR(C13/C12-1,0) -> -0.27657626 | F13: =IFERROR(D13/D12-1,0) -> -0.075892857 | G13: =IFERROR(C13/D13,0) -> 14290.323 | H13: 7
B14: =EDATE(B13,1) -> 45870 | C14: =SUMIFS(TransactionTable[Amount],TransactionTable[Transaction_Date],">="&B14,TransactionTable[Transaction_Date],"<"&EDATE(B14,1)) -> 2919928 | D14: =COUNTIFS(TransactionTable[Transaction_Date],">="&B14,TransactionTable[Transaction_Date],"<"&EDATE(B14,1)) -> 204 | E14: =IFERROR(C14/C13-1,0) -> -0.012903198 | F14: =IFERROR(D14/D13-1,0) -> -0.014492754 | G14: =IFERROR(C14/D14,0) -> 14313.372 | H14: 8
B15: =EDATE(B14,1) -> 45901 | C15: =SUMIFS(TransactionTable[Amount],TransactionTable[Transaction_Date],">="&B15,TransactionTable[Transaction_Date],"<"&EDATE(B15,1)) -> 3029489.4 | D15: =COUNTIFS(TransactionTable[Transaction_Date],">="&B15,TransactionTable[Transaction_Date],"<"&EDATE(B15,1)) -> 193 | E15: =IFERROR(C15/C14-1,0) -> 0.037521953 | F15: =IFERROR(D15/D14-1,0) -> -0.053921569 | G15: =IFERROR(C15/D15,0) -> 15696.836 | H15: 9
B16: =EDATE(B15,1) -> 45931 | C16: =SUMIFS(TransactionTable[Amount],TransactionTable[Transaction_Date],">="&B16,TransactionTable[Transaction_Date],"<"&EDATE(B16,1)) -> 3729052.5 | D16: =COUNTIFS(TransactionTable[Transaction_Date],">="&B16,TransactionTable[Transaction_Date],"<"&EDATE(B16,1)) -> 250 | E16: =IFERROR(C16/C15-1,0) -> 0.23091785 | F16: =IFERROR(D16/D15-1,0) -> 0.29533679 | G16: =IFERROR(C16/D16,0) -> 14916.21 | H16: 10
B17: =EDATE(B16,1) -> 45962 | C17: =SUMIFS(TransactionTable[Amount],TransactionTable[Transaction_Date],">="&B17,TransactionTable[Transaction_Date],"<"&EDATE(B17,1)) -> 3039172.8 | D17: =COUNTIFS(TransactionTable[Transaction_Date],">="&B17,TransactionTable[Transaction_Date],"<"&EDATE(B17,1)) -> 211 | E17: =IFERROR(C17/C16-1,0) -> -0.18500135 | F17: =IFERROR(D17/D16-1,0) -> -0.156 | G17: =IFERROR(C17/D17,0) -> 14403.663 | H17: 11
B18: =EDATE(B17,1) -> 45992 | C18: =SUMIFS(TransactionTable[Amount],TransactionTable[Transaction_Date],">="&B18,TransactionTable[Transaction_Date],"<"&EDATE(B18,1)) -> 3258274.9 | D18: =COUNTIFS(TransactionTable[Transaction_Date],">="&B18,TransactionTable[Transaction_Date],"<"&EDATE(B18,1)) -> 234 | E18: =IFERROR(C18/C17-1,0) -> 0.07209267 | F18: =IFERROR(D18/D17-1,0) -> 0.10900474 | G18: =IFERROR(C18/D18,0) -> 13924.252 | H18: 12
B19: FY 2025 | C19: =SUM(C7:C18) -> 36963243 | D19: =SUM(D7:D18) -> 2500 | G19: =IFERROR(C19/D19,0) -> 14785.297
B21: GROWTH DIAGNOSTICS
B22: Metric | D22: Value | E22: Interpretation
B23: Average MoM Value Growth | D23: =AVERAGE(E8:E18) -> 0.051892234 | E23: Mean of 11 month-on-month changes
B24: Average MoM Volume Growth | D24: =AVERAGE(F8:F18) -> 0.031163573 | E24: Mean of 11 month-on-month changes
B25: Compound Monthly Growth (Value, Jan→Dec) | D25: =(C18/C7)^(1/11)-1 -> 0.020235182 | E25: Smooths monthly volatility
B26: H2 vs H1 Value Growth | D26: =SUM(C13:C18)/SUM(C7:C12)-1 -> 0.050184416 | E26: Jul–Dec vs Jan–Jun
B27: H2 vs H1 Volume Growth | D27: =SUM(D13:D18)/SUM(D7:D12)-1 -> 0.081598668 | E27: Jul–Dec vs Jan–Jun
B28: Peak Value Month | D28: =INDEX(B7:B18,MATCH(MAX(C7:C18),C7:C18,0)) -> 45809 | E28: Highest monthly value
B29: Lowest Value Month | D29: =INDEX(B7:B18,MATCH(MIN(C7:C18),C7:C18,0)) -> 45748 | E29: Lowest monthly value
B30: Linear Trend Slope (₦ per month) | D30: =SLOPE(C7:C18,H7:H18) -> 48355.249 | E30: Least-squares trend of monthly value
B31: Overall Value Trend | D31: =IF(D30>0,"Increasing","Decreasing") -> Increasing | E31: Direction of the fitted trend line
B32: Overall Volume Trend | D32: =IF(SLOPE(D7:D18,H7:H18)>0,"Increasing","Decreasing") -> Increasing | E32: Direction of the fitted trend line

Sheet Obj6_Business_Drivers_Summary
B2: OBJECTIVE 6 · BUSINESS DRIVERS — EXECUTIVE BRIEF
B3: Core question: What key factors drive transaction activity and value in Nigerian FinTech? Every number in blue-grey 'live' cells is formula-linked to the analysis sheets and recalculates with the data.
B5: 1. EXECUTIVE SUMMARY
B6: ="In FY2025 the platform processed "&TEXT(Obj1_Volume_and_Value!C8,"#,##0")&" transactions worth ₦"&TEXT(Obj1_Volume_and_Value!C7,"#,##0.00")&" (average ₦"&TEXT(Obj1_Volume_and_Value!C9,"#,##0.00")&"). Activity is concentrated in "&Obj4_Geographic_Distribution!C7&" ("&TEXT(Obj4_Geographic_Distribution!G7,"0.0%")&" of value) and value is driven by Transfers ("&TEXT(Obj3_Product_Popularity!G7,"0.0%")&" of value). "&TEXT(Obj1_Volume_and_Value!C11,"0.0%")&" of transactions failed, leaving ₦"&TEXT(Obj1_Volume_and_Value!E17,"#,##0.00")&" of value unrealised. "&"Monthly value is volatile but the full-year trend is "&LOWER(Obj5_Growth_Trajectory!D31)&" (H2 vs H1: "&TEXT(Obj5_Growth_Trajectory!D26,"+0.0%;-0.0%")&")." -> In FY2025 the platform processed 2,500 transactions worth ₦36,963,242.61 (average ₦14,785.30). Activity is concentrated in Lagos (38.6% of value) and value is driven by Transfers (75.4% of value). 9.6% of transactions failed, leaving ₦3,743,318.15 of value unrealised. Monthly value is volatile but the full-year trend is increasing (H2 vs H1: +5.0%).
B8: 2. ANSWERS TO CORE MANAGEMENT QUESTIONS
B9: Objective | C9: Management Question | D9: Answer (live, formula-driven)
B10: Obj 1 · Volume & Value | C10: How much total money is being transacted? What are the key platform metrics? | D10: ="₦"&TEXT(Obj1_Volume_and_Value!C7,"#,##0.00")&" across "&TEXT(Obj1_Volume_and_Value!C8,"#,##0")&" transactions; average ticket ₦"&TEXT(Obj1_Volume_and_Value!C9,"#,##0.00")&". Success rate "&TEXT(Obj1_Volume_and_Value!C10,"0.0%")&", failure rate "&TEXT(Obj1_Volume_and_Value!C11,"0.0%")&", pending "&TEXT(Obj1_Volume_and_Value!D18,"0.0%")&"." -> ₦36,963,242.61 across 2,500 transactions; average ticket ₦14,785.30. Success rate 88.3%, failure rate 9.6%, pending 2.1%.
B11: Obj 2 · High-Value Customers | C11: Which customer segments and top individuals generate the most value? | D11: ="Top customer "&Obj2_High_Value_Customers!C7&" ("&Obj2_High_Value_Customers!D7&", "&Obj2_High_Value_Customers!E7&") transacted ₦"&TEXT(Obj2_High_Value_Customers!F7,"#,##0.00")&". The Top 10 hold only "&TEXT(Obj2_High_Value_Customers!H17,"0.0%")&" of value — revenue is broad-based across "&TEXT(Obj2_High_Value_Customers!C27,"#,##0")&" customers. Savings accounts ("&TEXT(Obj2_High_Value_Customers!G23,"0.0%")&") and the 35-49 age group ("&TEXT(Obj2_High_Value_Customers!H34,"0.0%")&") are the largest value segments." -> Top customer CUST-0179 (Delta, Tier 1 Wallet) transacted ₦374,370.26. The Top 10 hold only 7.8% of value — revenue is broad-based across 350 customers. Savings accounts (50.0%) and the 35-49 age group (43.4%) are the largest value segments.
B12: Obj 3 · Product Popularity | C12: Which transaction types and payment methods dominate counts vs value? | D12: ="By value: "&INDEX(Obj3_Product_Popularity!B7:B11,MATCH(1,Obj3_Product_Popularity!I7:I11,0))&" leads ("&TEXT(INDEX(Obj3_Product_Popularity!G7:G11,MATCH(1,Obj3_Product_Popularity!I7:I11,0)),"0.0%")&" of value). Airtime/Data is a volume product: "&TEXT(Obj3_Product_Popularity!D8,"0.0%")&" of count but "&TEXT(Obj3_Product_Popularity!G8,"0.0%")&" of value (avg ₦"&TEXT(Obj3_Product_Popularity!F8,"#,##0.00")&"). "&INDEX(Obj3_Product_Popularity!B18:B21,MATCH(1,Obj3_Product_Popularity!I18:I21,0))&" is the top channel ("&TEXT(INDEX(Obj3_Product_Popularity!G18:G21,MATCH(1,Obj3_Product_Popularity!I18:I21,0)),"0.0%")&" of value)." -> By value: Transfer leads (75.4% of value). Airtime/Data is a volume product: 26.4% of count but 3.1% of value (avg ₦1,717.67). Bank Transfer is the top channel (49.7% of value).
B13: Obj 4 · Geography | C13: Which Nigerian states show the highest activity and revenue? | D13: =Obj4_Geographic_Distribution!C7&" leads with ₦"&TEXT(Obj4_Geographic_Distribution!D7,"#,##0.00")&" ("&TEXT(Obj4_Geographic_Distribution!G7,"0.0%")&" of revenue, "&TEXT(Obj4_Geographic_Distribution!E7,"#,##0")&" txns), followed by "&Obj4_Geographic_Distribution!C8&" and "&Obj4_Geographic_Distribution!C9&". Key hubs Lagos + FCT Abuja + Rivers generate "&TEXT(Obj4_Geographic_Distribution!G25,"0.0%")&" of revenue." -> Lagos leads with ₦14,255,386.97 (38.6% of revenue, 985 txns), followed by Kano and Oyo. Key hubs Lagos + FCT Abuja + Rivers generate 55.4% of revenue.
B14: Obj 5 · Growth | C14: Are volumes and values increasing or decreasing month-over-month? | D14: ="MoM value growth swung between "&TEXT(MIN(Obj5_Growth_Trajectory!E8:E18),"0.0%")&" and "&TEXT(MAX(Obj5_Growth_Trajectory!E8:E18),"+0.0%")&", but the trend is "&LOWER(Obj5_Growth_Trajectory!D31)&": H2 value "&TEXT(Obj5_Growth_Trajectory!D26,"+0.0%;-0.0%")&" and volume "&TEXT(Obj5_Growth_Trajectory!D27,"+0.0%;-0.0%")&" vs H1; Dec vs Jan value "&TEXT(Obj5_Growth_Trajectory!C18/Obj5_Growth_Trajectory!C7-1,"+0.0%;-0.0%")&". Peak month: "&TEXT(Obj5_Growth_Trajectory!D28,"mmm yyyy")&"." -> MoM value growth swung between -34.1% and +58.4%, but the trend is increasing: H2 value +5.0% and volume +8.2% vs H1; Dec vs Jan value +24.7%. Peak month: Jun 2025.
B15: Obj 6 · Business Drivers | C15: What key factors drive transaction activity and value? | D15: Four drivers explain performance: (1) urban-hub concentration in Lagos; (2) a product mix where Transfers carry value while low-ticket utilities (Airtime/Data, Bills) carry frequency; (3) a ~9–10% technical failure rate that leaks value uniformly across segments; and (4) prime-age (25–49) Savings customers, with low Tier 3 (full-KYC) adoption capping ticket sizes.
B17: 3. BUSINESS DRIVER COMMENTARY
B18: Business Driver | C18: Key Evidence (live) | D18: Analytical Commentary | E18: Recommended Action
B19: Urban Hub Dominance | C19: ="Lagos: "&TEXT(SUMIF(TransactionTable[State],"Lagos",TransactionTable[Amount])/SUM(TransactionTable[Amount]),"0.0%")&" of value, "&TEXT(COUNTIF(TransactionTable[State],"Lagos")/COUNTA(TransactionTable[Transaction_ID]),"0.0%")&" of volume"&CHAR(10)&"Lagos + FCT Abuja + Rivers: "&TEXT(Obj4_Geographic_Distribution!G25,"0.0%")&" of value"&CHAR(10)&"State avg ticket range: ₦"&TEXT(MIN(Obj4_Geographic_Distribution!F7:F16),"#,##0")&" – ₦"&TEXT(MAX(Obj4_Geographic_Distribution!F7:F16),"#,##0") -> Lagos: 38.6% of value, 39.4% of volume Lagos + FCT Abuja + Rivers: 55.4% of value State avg ticket range: ₦13,065 – ₦17,333 | D19: Activity is heavily concentrated in Lagos, which alone generates roughly 2 of every 5 naira transacted — more than the next four states combined (Kano, Oyo, FCT Abuja, Rivers). The three designated hubs together account for over half of platform value. Average ticket sizes are broadly similar across states, so Lagos dominance is driven by user density and transaction frequency, not bigger transactions. Kaduna and Enugu are clearly under-penetrated. | E19: Protect the Lagos base with reliability SLAs and merchant/agent density. Prioritise growth in Kano (2nd by value) and under-penetrated northern and south-eastern states (Kaduna, Enugu) where average tickets are healthy but user counts are low.
B20: Product Utility vs Ticket Sizes | C20: ="Transfer: "&TEXT(Obj3_Product_Popularity!D7,"0.0%")&" of volume → "&TEXT(Obj3_Product_Popularity!G7,"0.0%")&" of value (avg ₦"&TEXT(Obj3_Product_Popularity!F7,"#,##0")&")"&CHAR(10)&"Airtime/Data: "&TEXT(Obj3_Product_Popularity!D8,"0.0%")&" of volume → "&TEXT(Obj3_Product_Popularity!G8,"0.0%")&" of value (avg ₦"&TEXT(Obj3_Product_Popularity!F8,"#,##0")&")" -> Transfer: 43.4% of volume → 75.4% of value (avg ₦25,700) Airtime/Data: 26.4% of volume → 3.1% of value (avg ₦1,718) | D20: Transfers are the value engine: under half of all transactions but three-quarters of value, at the highest average ticket. Airtime/Data is the engagement engine: second by count yet last by value — high-frequency, low-ticket utility usage that keeps customers active daily. Bill Payment and POS sit in the middle; Card Withdrawal is small on both measures. | E20: Use low-ticket utilities (airtime, bills) as acquisition and daily-engagement hooks, then cross-sell into transfers. Treat transfers as the core revenue line: optimise fee tiers, and protect limits and uptime on the transfer rail.
B21: Revenue Impact of Technical Failures (~9%) | C21: ="Failed: "&TEXT(Obj1_Volume_and_Value!C17,"#,##0")&" txns ("&TEXT(Obj1_Volume_and_Value!C11,"0.0%")&") = ₦"&TEXT(Obj1_Volume_and_Value!E17,"#,##0.00")&" ("&TEXT(Obj1_Volume_and_Value!F17,"0.0%")&" of value)"&CHAR(10)&"Pending: ₦"&TEXT(Obj1_Volume_and_Value!E18,"#,##0.00")&CHAR(10)&"Each 1pp cut in failure rate ≈ ₦"&TEXT(Obj1_Volume_and_Value!C7*0.01,"#,##0")&" recovered" -> Failed: 239 txns (9.6%) = ₦3,743,318.15 (10.1% of value) Pending: ₦906,651.76 Each 1pp cut in failure rate ≈ ₦369,632 recovered | D21: Roughly one in eleven transactions fails, leaking about a tenth of attempted value, with pending transactions adding further exposure. Failed transactions carry a slightly higher average ticket than successful ones, so failures hit value disproportionately. Failure rates are fairly uniform across account tiers and channels (USSD slightly higher, Wallet Balance lowest), pointing to a platform/switch-level reliability issue rather than a segment-specific one. | E21: Set a target to bring failure rate below 5%. Implement smart auto-retry and instant reversals, monitor USSD and interbank gateway uptime, and clear pending transactions within T+1. Report failed value weekly as a revenue-at-risk KPI.
